Workbook
Name Receitas: X!$V$2:$V$15
Name CatReceitas: 'Plano de Contas'!$B$4:$H$4
Name RecebimentosVencidos: XX!$A$1:$K$999
Name MesAtual: X!$Q$5
Name Plano_receitas: 'Plano de Contas'!$B$5:$H$195
Name Categorias: X!$V$2:$V$15
Name bancos: Cadastros!$B$6:$B$19
Name Tcentrocustos: X!$G$2:$G$6
Name CatDespesas: 'Plano de Contas'!$J$4:$Z$4
Name Meses: X!$I$2:$I$14
Name CentroCustos: Cadastros!$M$6:$M$19
Name Fornecedores: Cadastros!$I$6:$I$998
Name formaspgto: Cadastros!$K$6:$K$79
Name Tfornecedores: X!$N$2:$N$1001
Name Tbancos: X!$A$2:$A$1001
Name plano_despesas: 'Plano de Contas'!$J$5:$Z$195
Name Clientes: Cadastros!$G$6:$G$998
Name Tclientes: X!$L$2:$L$1001

Sheet inicio
A2: IMPORTANTE | H2: ACESSE NOSSO SITE E CONHEÇA NOSSAS OUTRAS PLANILHAS
H3: macrobit.com.br
A4: Para utilizar sua planilha você deve clicar em "Arquivo" e depois em "Fazer Cópia"! Assim você salvará uma cópia associada a sua conta google.
A8: Jamais peça acesso a planilha da Macro Bit, o procedimento correto é salvar a sua própria cópia do arquivo Raiz!
A11: Em caso de dúvidas, chame nosso suporte no whatsapp: (22) 98152-6045

Sheet Plano de Contas
B2: CATEGORIAS DE RECEITAS | J2: CATEGORIAS DE DESPESAS
B4: Receitas Operacionais | D4: Outras Receitas Operacionais | F4: Receitas Financeiras | H4: Receitas não operacionais | J4: Deduções sobre vendas | L4: Custo das Vendas | N4: Despesas administrativas | P4: Despesa com Pessoal | R4: Despesa Comercial | T4: Despesa Financeira | V4: Despesas não operacionais | X4: Impostos | Z4: Participação e Dividendos
B5: Dinheiro | D5: Entradas Caixinha | F5: Juros | H5: Aportes de Sócio | J5: Comissão 10% | L5: Pão | N5: Luz | P5: Salários | T5: Tarifas Bancárias | V5: Financiamento | X5: PIS | Z5: Retiradas dos Sócios
B6: Credito | F6: Rentabilidade de Aplicações | H6: Venda de bens - Valor residual | J6: Motoboy | L6: Carne | N6: Água | P6: 13º Salário | T6: Taxas e Desp. de Cobrança | V6: Gastos Não Identificados | X6: COFINS | Z6: Participação no Lucro
B7: Debito | H7: Empréstimos bancários | J7: Tx. Cartão | L7: Queijos | N7: Internet | P7: Adiantamento Salarial | T7: Outras Despesas Financeiras | V7: Investimento em Patrimonio | X7: CSLL
B8: Pix | H8: Valores de terceiros | J8: Devoluções | L8: Bacon | N8: Aluguel | P8: Aquisição de Equipamentos | T8: Juros | V8: Combustível | X8: INSS - Funcionarios
B9: Ifood | H9: Empréstimo Luiz | J9: DAS | L9: Congelados | N9: Contador | P9: Assistência médica | T9: Multas | V9: Doblô | X9: INSS - Patronal
B10: V. Refeição | H10: Empréstimo Diogo | J10: Taxa Ifood | L10: Picanha e Costela | N10: Marketing | P10: Bonificação Fixo | T10: IOF | V10: Obras e Manutenção | X10: IRRF
H11: Emprestimo Iago | L11: Frutas | N11: Segurança | P11: Férias | V11: Empréstimos Luiz | X11: ISS
L12: Gás | N12: Sistema | P12: FGTS | V12: Empréstimos Diogo | X12: ICMS
L13: Bebidas | N13: Limpeza | P13: Horas-extras | V13: Tarifas
L14: Mercado | P14: INSS (funcionários) | V14: Diferença de Caixa
P15: INSS (patronal) | V15: Multas e Juros
P16: IRPF | V16: Outros
P17: Plano de saúde dos Sócios
P18: Pró labore
P19: Refeição de Funcionários / Ticket
P20: Rescisões trabalhistas
P21: Salários Escritório
P22: Seguro de Vida
P23: Treinamentos e Capacitações
P24: Uniformes / EPI / EPC
P25: Vale-transportes

Sheet Cadastros
B2: Cadastros
B5: CONTAS BANCÁRIAS | C5: Centro de Custos | D5: SALDO | E5: DATA | G5: Clientes | I5: Fornecedores | K5: Formas de Pagamento | M5: Centro de Custos
B6: Banco Inter | C6: Projeto 01 | D6: 5240 | E6: 44562 | G6: Rogério Ceni | I6: Fornecedor 01 | K6: Dinheiro | M6: Projeto 01
B7: Nubank | C7: Projeto 02 | D7: 2500 | E7: 44562 | G7: Roger Machado | I7: Fornecedor 02 | K7: Pix | M7: Projeto 02
G8: Luiz Castro | I8: Fornecedor 03 | K8: Cartão | M8: Projeto 03
G9: Rafael Paiva | K9: Boleto | M9: Projeto 04

Sheet Entradas
B2: Descrição | C2: Categoria | D2: Classificação | E2: Data da Competência | F2: Data do Recebimento | G2: Status | H2: Cliente | I2: Valores | J2: Forma de Recebimento | K2: Conta Financeira | L2: Centro de Custos
B3: Vendas em dinheiro | C3: Receitas Operacionais | D3: Dinheiro | E3: 45973 | F3: 45973 | G3: Realizado | H3: Rogério Ceni | I3: 500 | J3: Dinheiro | K3: Banco Inter | L3: Projeto 01
B4: Vendas em dinheiro | C4: Receitas Operacionais | D4: Dinheiro | E4: 45974 | F4: 45974 | G4: Realizado | H4: Roger Machado | I4: 350 | J4: Pix | K4: Nubank | L4: Projeto 02
B5: Vendas em pix | C5: Receitas Operacionais | D5: Dinheiro | E5: 45975 | F5: 45975 | G5: Previsto | H5: Luiz Castro | I5: 500 | J5: Cartão | K5: Banco Inter | L5: Projeto 01
B6: Vendas Crédito | C6: Receitas Operacionais | D6: Dinheiro | E6: 45976 | F6: 45976 | G6: Realizado | H6: Rafael Paiva | I6: 3500 | J6: Boleto | K6: Nubank | L6: Projeto 02
B7: Vendas no débito | C7: Receitas Operacionais | D7: Dinheiro | E7: 45977 | F7: 45977 | G7: Realizado | H7: Rogério Ceni | I7: 2500 | J7: Dinheiro | K7: Banco Inter | L7: Projeto 01
B8: Vendas em dinheiro | C8: Receitas Operacionais | D8: Dinheiro | E8: 45978 | F8: 45978 | G8: Realizado | H8: Roger Machado | I8: 350 | J8: Pix | K8: Nubank | L8: Projeto 02
B9: Vendas em pix | C9: Receitas Operacionais | D9: Dinheiro | E9: 45979 | F9: 45979 | G9: Previsto | H9: Luiz Castro | I9: 800 | J9: Cartão | K9: Banco Inter | L9: Projeto 01
B10: Vendas Crédito | C10: Receitas Operacionais | D10: Dinheiro | E10: 45980 | F10: 45980 | G10: Realizado | H10: Rafael Paiva | I10: 1200 | J10: Boleto | K10: Nubank | L10: Projeto 02
B11: Vendas no débito | C11: Receitas Operacionais | D11: Dinheiro | E11: 45981 | F11: 45981 | G11: Realizado | H11: Rogério Ceni | I11: 500 | J11: Dinheiro | K11: Banco Inter | L11: Projeto 01
B12: Vendas em dinheiro | C12: Receitas Operacionais | D12: Dinheiro | E12: 45982 | F12: 45982 | G12: Realizado | H12: Roger Machado | I12: 350 | J12: Pix | K12: Nubank | L12: Projeto 02
B13: Vendas em pix | C13: Receitas Operacionais | D13: Dinheiro | E13: 45983 | F13: 45983 | G13: Previsto | H13: Luiz Castro | I13: 800 | J13: Cartão | K13: Banco Inter | L13: Projeto 01
B14: Vendas Crédito | C14: Receitas Operacionais | D14: Dinheiro | E14: 45984 | F14: 45984 | G14: Realizado | H14: Rafael Paiva | I14: 1200 | J14: Boleto | K14: Nubank | L14: Projeto 02
... B26: Vendas no Crédito | C26: Receitas Operacionais | D26: Dinheiro | E26: 45996 | F26: 45996 | G26: Previsto | H26: Rafael Paiva | I26: 2500 | J26: Boleto | K26: Nubank | L26: Projeto 02

Sheet Saídas
B2: Descrição | C2: Categoria | D2: Classificação | E2: Data da Competência | F2: Data do Pagamento | G2: Status | H2: Fornecedor | I2: Valores | J2: Forma de Recebimento | K2: Conta Financeira | L2: Centro de Custos
B3: Compra de queijo | C3: Custo das Vendas | D3: Pão | E3: 45973 | F3: 45973 | G3: Previsto | H3: Fornecedor 01 | I3: 123 | J3: Dinheiro | K3: Banco Inter | L3: Projeto 01
B4: Bebidas | C4: Custo das Vendas | D4: Bebidas | E4: 45974 | F4: 45974 | G4: Realizado | H4: Fornecedor 02 | I4: 250 | J4: Pix | K4: Nubank | L4: Projeto 02
B5: Salário José | C5: Despesa com Pessoal | D5: Salários | E5: 45975 | F5: 45975 | G5: Previsto | H5: Fornecedor 03 | I5: 1320 | J5: Cartão | K5: Banco Inter | L5: Projeto 01
B6: Salário Mária | C6: Despesa com Pessoal | D6: Salários | E6: 45976 | F6: 45976 | G6: Previsto | H6: Fornecedor 01 | I6: 1320 | J6: Boleto | K6: Nubank | L6: Projeto 02
B7: Aluguel | C7: Despesas administrativas | D7: Aluguel | E7: 45977 | F7: 45977 | G7: Previsto | H7: Fornecedor 02 | I7: 1320 | J7: Dinheiro | K7: Banco Inter | L7: Projeto 01
B8: Luz | C8: Despesas administrativas | D8: Luz | E8: 45978 | F8: 45978 | G8: Previsto | H8: Fornecedor 03 | I8: 450 | J8: Pix | K8: Nubank | L8: Projeto 02
B9: Pão | C9: Custo das Vendas | D9: Pão | E9: 45979 | F9: 45979 | G9: Realizado | H9: Fornecedor 01 | I9: 450 | J9: Cartão | K9: Banco Inter | L9: Projeto 01
B10: Salário José | C10: Despesa com Pessoal | D10: Salários | E10: 45980 | F10: 45980 | G10: Previsto | H10: Fornecedor 02 | I10: 1320 | J10: Boleto | K10: Nubank | L10: Projeto 02
B11: Salário Mária | C11: Despesa com Pessoal | D11: Salários | E11: 45981 | F11: 45981 | G11: Previsto | H11: Fornecedor 03 | I11: 1320 | J11: Dinheiro | K11: Banco Inter | L11: Projeto 01
B12: Aluguel | C12: Despesas administrativas | D12: Aluguel | E12: 45982 | F12: 45982 | G12: Previsto | H12: Fornecedor 01 | I12: 2500 | J12: Pix | K12: Nubank | L12: Projeto 02
B13: Taxa do cartão | C13: Deduções Sobre Vendas | D13: Taxas e Desp. de Cobrança | E13: 45983 | F13: 45983 | G13: Realizado | H13: Fornecedor 02 | I13: 925 | J13: Cartão | K13: Banco Inter | L13: Projeto 01
B14: Impostos | C14: Impostos | D14: DAS | E14: 45984 | F14: 45984 | G14: Realizado | H14: Fornecedor 03 | I14: 650 | J14: Boleto | K14: Nubank | L14: Projeto 02
... B18: Teste de caixa negativo | C18: Despesas não operacionais | D18: Investimento em Patrimonio | E18: 45988 | F18: 45988 | G18: Previsto | H18: Fornecedor 01 | I18: 35000 | J18: Cartão | K18: Nubank | L18: Projeto 02

Sheet Transf Interna
B2: Conta de Origem | C2: Conta de Destino | D2: Data | E2: Valor
B3: Banco Inter | C3: Nubank | D3: 44927 | E3: 1500
B4: Banco Inter | C4: Nubank | D4: 44958 | E4: 1500
B5: Banco Inter | C5: Nubank | D5: 44986 | E5: 50000
B6: Banco Inter | C6: Nubank | D6: 45017 | E6: 1500
B7: Banco Inter | C7: Nubank | D7: 45047 | E7: 1500
B8: Banco Inter | C8: Nubank | D8: 45078 | E8: 1500
B9: Banco Inter | C9: Nubank | D9: 45108 | E9: 1500

Sheet Contas a Receber
B2: Contas a Receber | D2: FILTROS PARA CONTAS A RECEBER | K2: CONTAS A RECEBER
D3: Ano: | E3: 2025 | K3: Inicio | L3: =DATE( 'Contas a Receber'!E3,VLOOKUP('Contas a Receber'!$E$4,X!$I$2:$J$14,2,FALSE),1) -> 45658
B4: TOTAL A RECEBER | D4: Mês: | E4: Todos
B5: =SUM(E9:E1005) -> 16600 | D5: Cliente: | E5: Todos | K5: Final | L5: =IF('Contas a Receber'!E4="Todos",EDATE(L3,12),EDATE(L3,1)) -> 46023
D6: Centro de custos: | E6: Todos
B8: Descrição da conta | C8: Cliente | D8: Vencimento | E8: Valor
B9: =IFERROR(__xludf.DUMMYFUNCTION("IFERROR( INDEX( SORT( FILTER( {Entradas[Data do Recebimento],Entradas[Descrição]}, Entradas[Status]=""Previsto"", Entradas[Data do Recebimento]>='Contas a Receber'!$L$3, Entradas[Data do Recebimento]<'Contas a R"&"eceber'!$L$5, IF($E$5=""Todos"", Entradas[Cliente]<>""-"", Entradas[Cliente]=$E$5), IF(E6=""Todos"", Entradas[Centro de Custos]<>""-"", Entradas[Centro de Custos]=E6) ), 1, TRUE ), ,2 ), ""Não há contas com o filtro"&" selecionado"" ) "),"Vendas em pix") -> Vendas em pix | C9: =IFERROR(__xludf.DUMMYFUNCTION("IFERROR( INDEX( SORT( FILTER( {Entradas[Data do Recebimento],Entradas[Cliente]}, Entradas[Status]=""Previsto"", Entradas[Data do Recebimento]>='Contas a Receber'!$L$3, Entradas[Data do Recebimento]<'Contas a Rec"&"eber'!$L$5, IF($E$5=""Todos"", Entradas[Cliente]<>""-"", Entradas[Cliente]=$E$5), IF(E6=""Todos"", Entradas[Centro de Custos]<>""-"", Entradas[Centro de Custos]=E6) ), 1, TRUE ), ,2 ), ""Não há contas com o filtro s"&"elecionado"" ) "),"Luiz Castro") -> Luiz Castro | D9: =IFERROR(__xludf.DUMMYFUNCTION("IFERROR( INDEX( SORT( FILTER( {Entradas[Data do Recebimento],Entradas[Data do Recebimento]}, Entradas[Status]=""Previsto"", Entradas[Data do Recebimento]>='Contas a Receber'!$L$3, Entradas[Data do Recebimento]<'"&"Contas a Receber'!$L$5, IF($E$5=""Todos"", Entradas[Cliente]<>""-"", Entradas[Cliente]=$E$5), IF(E6=""Todos"", Entradas[Centro de Custos]<>""-"", Entradas[Centro de Custos]=E6) ), 1, TRUE ), ,2 ), ""Não há contas co"&"m o filtro selecionado"" ) "),45975.0) -> 45975 | E9: =IFERROR(__xludf.DUMMYFUNCTION("IFERROR( INDEX( SORT( FILTER( {Entradas[Data do Recebimento],Entradas[Valores]}, Entradas[Status]=""Previsto"", Entradas[Data do Recebimento]>='Contas a Receber'!$L$3, Entradas[Data do Recebimento]<'Contas a Rec"&"eber'!$L$5, IF($E$5=""Todos"", Entradas[Cliente]<>""-"", Entradas[Cliente]=$E$5), IF(E6=""Todos"", Entradas[Centro de Custos]<>""-"", Entradas[Centro de Custos]=E6) ), 1, TRUE ), ,2 ), ""Não há contas com o filtro s"&"elecionado"" ) "),500.0) -> 500
B10: =IFERROR(__xludf.DUMMYFUNCTION("""COMPUTED_VALUE"""),"Vendas em pix") -> Vendas em pix | C10: =IFERROR(__xludf.DUMMYFUNCTION("""COMPUTED_VALUE"""),"Luiz Castro") -> Luiz Castro | D10: =IFERROR(__xludf.DUMMYFUNCTION("""COMPUTED_VALUE"""),45979.0) -> 45979 | E10: =IFERROR(__xludf.DUMMYFUNCTION("""COMPUTED_VALUE"""),800.0) -> 800
B11: =IFERROR(__xludf.DUMMYFUNCTION("""COMPUTED_VALUE"""),"Vendas em pix") -> Vendas em pix | C11: =IFERROR(__xludf.DUMMYFUNCTION("""COMPUTED_VALUE"""),"Luiz Castro") -> Luiz Castro | D11: =IFERROR(__xludf.DUMMYFUNCTION("""COMPUTED_VALUE"""),45983.0) -> 45983 | E11: =IFERROR(__xludf.DUMMYFUNCTION("""COMPUTED_VALUE"""),800.0) -> 800
B12: =IFERROR(__xludf.DUMMYFUNCTION("""COMPUTED_VALUE"""),"Venda de carro João 1/3") -> Venda de carro João 1/3 | C12: =IFERROR(__xludf.DUMMYFUNCTION("""COMPUTED_VALUE"""),"Roger Machado") -> Roger Machado | D12: =IFERROR(__xludf.DUMMYFUNCTION("""COMPUTED_VALUE"""),45986.0) -> 45986 | E12: =IFERROR(__xludf.DUMMYFUNCTION("""COMPUTED_VALUE"""),5000.0) -> 5000
B13: =IFERROR(__xludf.DUMMYFUNCTION("""COMPUTED_VALUE"""),"Venda de carro João 2/3") -> Venda de carro João 2/3 | C13: =IFERROR(__xludf.DUMMYFUNCTION("""COMPUTED_VALUE"""),"Luiz Castro") -> Luiz Castro | D13: =IFERROR(__xludf.DUMMYFUNCTION("""COMPUTED_VALUE"""),45987.0) -> 45987 | E13: =IFERROR(__xludf.DUMMYFUNCTION("""COMPUTED_VALUE"""),5000.0) -> 5000
B14: =IFERROR(__xludf.DUMMYFUNCTION("""COMPUTED_VALUE"""),"Vendas em pix") -> Vendas em pix | C14: =IFERROR(__xludf.DUMMYFUNCTION("""COMPUTED_VALUE"""),"Roger Machado") -> Roger Machado | D14: =IFERROR(__xludf.DUMMYFUNCTION("""COMPUTED_VALUE"""),45990.0) -> 45990 | E14: =IFERROR(__xludf.DUMMYFUNCTION("""COMPUTED_VALUE"""),800.0) -> 800
B15: =IFERROR(__xludf.DUMMYFUNCTION("""COMPUTED_VALUE"""),"Vendas no Débito") -> Vendas no Débito | C15: =IFERROR(__xludf.DUMMYFUNCTION("""COMPUTED_VALUE"""),"Luiz Castro") -> Luiz Castro | D15: =IFERROR(__xludf.DUMMYFUNCTION("""COMPUTED_VALUE"""),45995.0) -> 45995 | E15: =IFERROR(__xludf.DUMMYFUNCTION("""COMPUTED_VALUE"""),1200.0) -> 1200
B16: =IFERROR(__xludf.DUMMYFUNCTION("""COMPUTED_VALUE"""),"Vendas no Crédito") -> Vendas no Crédito | C16: =IFERROR(__xludf.DUMMYFUNCTION("""COMPUTED_VALUE"""),"Rafael Paiva") -> Rafael Paiva | D16: =IFERROR(__xludf.DUMMYFUNCTION("""COMPUTED_VALUE"""),45996.0) -> 45996 | E16: =IFERROR(__xludf.DUMMYFUNCTION("""COMPUTED_VALUE"""),2500.0) -> 2500

Sheet Contas a Pagar
B2: Contas a Receber | D2: FILTROS PARA CONTAS A RECEBER | K2: CONTAS A RECEBER
D3: Ano: | E3: 2025 | K3: Inicio | L3: =DATE( 'Contas a Pagar'!E3,VLOOKUP('Contas a Pagar'!$E$4,X!$I$2:$J$14,2,FALSE),1) -> 45658
B4: TOTAL A PAGAR | D4: Mês: | E4: Todos
B5: =SUM(E9:E1005) -> 55313 | D5: Fornecedor | E5: Todos | K5: Final | L5: =IF('Contas a Pagar'!E4="Todos",EDATE(L3,12),EDATE(L3,1)) -> 46023
D6: Centro de custos: | E6: Todos
B8: Descrição da conta | C8: Fornecedores | D8: Vencimento | E8: Valor
B9: =IFERROR(__xludf.DUMMYFUNCTION("IFERROR( INDEX( SORT( FILTER( {Saidas[Data do Pagamento],Saidas[Descrição]}, Saidas[Status]=""Previsto"", Saidas[Data do Pagamento]>='Contas a Pagar'!$L$3, Saidas[Data do Pagamento]<'Contas a Pagar'!$L$5, "&" IF($E$5=""Todos"", Saidas[Fornecedor]<>""-"", Saidas[Fornecedor]=$E$5), IF(E6=""Todos"", Saidas[Centro de Custos]<>""-"", Saidas[Centro de Custos]=E6) ), 1, TRUE ), ,2 ), ""Não há contas com o filtro selecionado"" ) "),"Compra de queijo") -> Compra de queijo | C9: =IFERROR(__xludf.DUMMYFUNCTION("IFERROR( INDEX( SORT( FILTER( {Saidas[Data do Pagamento],Saidas[Fornecedor]}, Saidas[Status]=""Previsto"", Saidas[Data do Pagamento]>='Contas a Pagar'!$L$3, Saidas[Data do Pagamento]<'Contas a Pagar'!$L$5, "&" IF($E$5=""Todos"", Saidas[Fornecedor]<>""-"", Saidas[Fornecedor]=$E$5), IF(E6=""Todos"", Saidas[Centro de Custos]<>""-"", Saidas[Centro de Custos]=E6) ), 1, TRUE ), ,2 ), ""Não há contas com o filtro selecionado"" ) "),"Fornecedor 01") -> Fornecedor 01 | D9: =IFERROR(__xludf.DUMMYFUNCTION("IFERROR( INDEX( SORT( FILTER( {Saidas[Data do Pagamento],Saidas[Data do Pagamento]}, Saidas[Status]=""Previsto"", Saidas[Data do Pagamento]>='Contas a Pagar'!$L$3, Saidas[Data do Pagamento]<'Contas a Pagar'!$L$5"&", IF($E$5=""Todos"", Saidas[Fornecedor]<>""-"", Saidas[Fornecedor]=$E$5), IF(E6=""Todos"", Saidas[Centro de Custos]<>""-"", Saidas[Centro de Custos]=E6) ), 1, TRUE ), ,2 ), ""Não há contas com o filtro selecionado"""&" ) "),45973.0) -> 45973 | E9: =IFERROR(__xludf.DUMMYFUNCTION("IFERROR( INDEX( SORT( FILTER( {Saidas[Data do Pagamento],Saidas[Valores]}, Saidas[Status]=""Previsto"", Saidas[Data do Pagamento]>='Contas a Pagar'!$L$3, Saidas[Data do Pagamento]<'Contas a Pagar'!$L$5, "&"IF($E$5=""Todos"", Saidas[Fornecedor]<>""-"", Saidas[Fornecedor]=$E$5), IF(E6=""Todos"", Saidas[Centro de Custos]<>""-"", Saidas[Centro de Custos]=E6) ), 1, TRUE ), ,2 ), ""Não há contas com o filtro selecionado"" ) "),123.0) -> 123
B10: =IFERROR(__xludf.DUMMYFUNCTION("""COMPUTED_VALUE"""),"Salário José") -> Salário José | C10: =IFERROR(__xludf.DUMMYFUNCTION("""COMPUTED_VALUE"""),"Fornecedor 03") -> Fornecedor 03 | D10: =IFERROR(__xludf.DUMMYFUNCTION("""COMPUTED_VALUE"""),45975.0) -> 45975 | E10: =IFERROR(__xludf.DUMMYFUNCTION("""COMPUTED_VALUE"""),1320.0) -> 1320
B11: =IFERROR(__xludf.DUMMYFUNCTION("""COMPUTED_VALUE"""),"Salário Mária") -> Salário Mária | C11: =IFERROR(__xludf.DUMMYFUNCTION("""COMPUTED_VALUE"""),"Fornecedor 01") -> Fornecedor 01 | D11: =IFERROR(__xludf.DUMMYFUNCTION("""COMPUTED_VALUE"""),45976.0) -> 45976 | E11: =IFERROR(__xludf.DUMMYFUNCTION("""COMPUTED_VALUE"""),1320.0) -> 1320
B12: =IFERROR(__xludf.DUMMYFUNCTION("""COMPUTED_VALUE"""),"Aluguel") -> Aluguel | C12: =IFERROR(__xludf.DUMMYFUNCTION("""COMPUTED_VALUE"""),"Fornecedor 02") -> Fornecedor 02 | D12: =IFERROR(__xludf.DUMMYFUNCTION("""COMPUTED_VALUE"""),45977.0) -> 45977 | E12: =IFERROR(__xludf.DUMMYFUNCTION("""COMPUTED_VALUE"""),1320.0) -> 1320
B13: =IFERROR(__xludf.DUMMYFUNCTION("""COMPUTED_VALUE"""),"Luz") -> Luz | C13: =IFERROR(__xludf.DUMMYFUNCTION("""COMPUTED_VALUE"""),"Fornecedor 03") -> Fornecedor 03 | D13: =IFERROR(__xludf.DUMMYFUNCTION("""COMPUTED_VALUE"""),45978.0) -> 45978 | E13: =IFERROR(__xludf.DUMMYFUNCTION("""COMPUTED_VALUE"""),450.0) -> 450
B14: =IFERROR(__xludf.DUMMYFUNCTION("""COMPUTED_VALUE"""),"Salário José") -> Salário José | C14: =IFERROR(__xludf.DUMMYFUNCTION("""COMPUTED_VALUE"""),"Fornecedor 02") -> Fornecedor 02 | D14: =IFERROR(__xludf.DUMMYFUNCTION("""COMPUTED_VALUE"""),45980.0) -> 45980 | E14: =IFERROR(__xludf.DUMMYFUNCTION("""COMPUTED_VALUE"""),1320.0) -> 1320
B15: =IFERROR(__xludf.DUMMYFUNCTION("""COMPUTED_VALUE"""),"Salário Mária") -> Salário Mária | C15: =IFERROR(__xludf.DUMMYFUNCTION("""COMPUTED_VALUE"""),"Fornecedor 03") -> Fornecedor 03 | D15: =IFERROR(__xludf.DUMMYFUNCTION("""COMPUTED_VALUE"""),45981.0) -> 45981 | E15: =IFERROR(__xludf.DUMMYFUNCTION("""COMPUTED_VALUE"""),1320.0) -> 1320
B16: =IFERROR(__xludf.DUMMYFUNCTION("""COMPUTED_VALUE"""),"Aluguel") -> Aluguel | C16: =IFERROR(__xludf.DUMMYFUNCTION("""COMPUTED_VALUE"""),"Fornecedor 01") -> Fornecedor 01 | D16: =IFERROR(__xludf.DUMMYFUNCTION("""COMPUTED_VALUE"""),45982.0) -> 45982 | E16: =IFERROR(__xludf.DUMMYFUNCTION("""COMPUTED_VALUE"""),2500.0) -> 2500
B17: =IFERROR(__xludf.DUMMYFUNCTION("""COMPUTED_VALUE"""),"Salário José") -> Salário José | C17: =IFERROR(__xludf.DUMMYFUNCTION("""COMPUTED_VALUE"""),"Fornecedor 01") -> Fornecedor 01 | D17: =IFERROR(__xludf.DUMMYFUNCTION("""COMPUTED_VALUE"""),45985.0) -> 45985 | E17: =IFERROR(__xludf.DUMMYFUNCTION("""COMPUTED_VALUE"""),1320.0) -> 1320
B18: =IFERROR(__xludf.DUMMYFUNCTION("""COMPUTED_VALUE"""),"Salário Mária") -> Salário Mária | C18: =IFERROR(__xludf.DUMMYFUNCTION("""COMPUTED_VALUE"""),"Fornecedor 02") -> Fornecedor 02 | D18: =IFERROR(__xludf.DUMMYFUNCTION("""COMPUTED_VALUE"""),45986.0) -> 45986 | E18: =IFERROR(__xludf.DUMMYFUNCTION("""COMPUTED_VALUE"""),1320.0) -> 1320
B19: =IFERROR(__xludf.DUMMYFUNCTION("""COMPUTED_VALUE"""),"Custo da Mercadoria") -> Custo da Mercadoria | C19: =IFERROR(__xludf.DUMMYFUNCTION("""COMPUTED_VALUE"""),"Fornecedor 03") -> Fornecedor 03 | D19: =IFERROR(__xludf.DUMMYFUNCTION("""COMPUTED_VALUE"""),45987.0) -> 45987 | E19: =IFERROR(__xludf.DUMMYFUNCTION("""COMPUTED_VALUE"""),8000.0) -> 8000
B20: =IFERROR(__xludf.DUMMYFUNCTION("""COMPUTED_VALUE"""),"Teste de caixa negativo") -> Teste de caixa negativo | C20: =IFERROR(__xludf.DUMMYFUNCTION("""COMPUTED_VALUE"""),"Fornecedor 01") -> Fornecedor 01 | D20: =IFERROR(__xludf.DUMMYFUNCTION("""COMPUTED_VALUE"""),45988.0) -> 45988 | E20: =IFERROR(__xludf.DUMMYFUNCTION("""COMPUTED_VALUE"""),35000.0) -> 35000

Sheet Fluxo de Caixa
B2: Fluxo de Caixa | D2: FILTROS DO FLUXO DE CAIXA
D3: Ano: | E3: 2025 | F3: Status: | G3: Previsto | H3: Banco: | I3: Todos | K3: Centro de custos: | L3: Todos
C6: =DATE(E3,1,1) -> 45658 | D6: =EDATE(C6,1) -> 45689 | E6: =EDATE(D6,1) -> 45717 | F6: =EDATE(E6,1) -> 45748 | G6: =EDATE(F6,1) -> 45778 | H6: =EDATE(G6,1) -> 45809 | I6: =EDATE(H6,1) -> 45839 | J6: =EDATE(I6,1) -> 45870 | K6: =EDATE(J6,1) -> 45901 | ... N6: =EDATE(M6,1) -> 45992 | O6: Total do Ano
B8: Saldo Inícial | C8: =SUMIFS(Entradas[Valores],Entradas[Data do Recebimento],"<"&C$6,Entradas[Status],X!$E$2,Entradas[Conta Financeira],X!$E$3)-SUMIFS(Saidas[Valores],Saidas[Data do Pagamento],"<"&C$6,Saidas[Status],X!$E$2,Saidas[Conta Financeira],X!$E$3)+SUMIFS(Cadastros!$D$6:$D$19,Cadastros!$E$6:$E$19,"<"&C6,Cadastros!$B$6:$B$19,X!$E$3)+SUMIFS(Transferência_Interna[Valor],Transferência_Interna[Conta de Destino],X!$E$3,Transferência_Interna[Data],"<"&C$6)-SUMIFS(Transferência_Interna[Valor],Transferência_Interna[Conta de Origem],X!$E$3,Transferência_Interna[Data],"<"&C$6) -> 7740 | D8: =SUMIFS(Entradas[Valores],Entradas[Data do Recebimento],"<"&D$6,Entradas[Status],X!$E$2,Entradas[Conta Financeira],X!$E$3)-SUMIFS(Saidas[Valores],Saidas[Data do Pagamento],"<"&D$6,Saidas[Status],X!$E$2,Saidas[Conta Financeira],X!$E$3)+SUMIFS(Cadastros!$D$6:$D$19,Cadastros!$E$6:$E$19,"<"&D6,Cadastros!$B$6:$B$19,X!$E$3)+SUMIFS(Transferência_Interna[Valor],Transferência_Interna[Conta de Destino],X!$E$3,Transferência_Interna[Data],"<"&D$6)-SUMIFS(Transferência_Interna[Valor],Transferência_Interna[Conta de Origem],X!$E$3,Transferência_Interna[Data],"<"&D$6) -> 7740 | E8: =SUMIFS(Entradas[Valores],Entradas[Data do Recebimento],"<"&E$6,Entradas[Status],X!$E$2,Entradas[Conta Financeira],X!$E$3)-SUMIFS(Saidas[Valores],Saidas[Data do Pagamento],"<"&E$6,Saidas[Status],X!$E$2,Saidas[Conta Financeira],X!$E$3)+SUMIFS(Cadastros!$D$6:$D$19,Cadastros!$E$6:$E$19,"<"&E6,Cadastros!$B$6:$B$19,X!$E$3)+SUMIFS(Transferência_Interna[Valor],Transferência_Interna[Conta de Destino],X!$E$3,Transferência_Interna[Data],"<"&E$6)-SUMIFS(Transferência_Interna[Valor],Transferência_Interna[Conta de Origem],X!$E$3,Transferência_Interna[Data],"<"&E$6) -> 7740 | F8: =SUMIFS(Entradas[Valores],Entradas[Data do Recebimento],"<"&F$6,Entradas[Status],X!$E$2,Entradas[Conta Financeira],X!$E$3)-SUMIFS(Saidas[Valores],Saidas[Data do Pagamento],"<"&F$6,Saidas[Status],X!$E$2,Saidas[Conta Financeira],X!$E$3)+SUMIFS(Cadastros!$D$6:$D$19,Cadastros!$E$6:$E$19,"<"&F6,Cadastros!$B$6:$B$19,X!$E$3)+SUMIFS(Transferência_Interna[Valor],Transferência_Interna[Conta de Destino],X!$E$3,Transferência_Interna[Data],"<"&F$6)-SUMIFS(Transferência_Interna[Valor],Transferência_Interna[Conta de Origem],X!$E$3,Transferência_Interna[Data],"<"&F$6) -> 7740 | G8: =SUMIFS(Entradas[Valores],Entradas[Data do Recebimento],"<"&G$6,Entradas[Status],X!$E$2,Entradas[Conta Financeira],X!$E$3)-SUMIFS(Saidas[Valores],Saidas[Data do Pagamento],"<"&G$6,Saidas[Status],X!$E$2,Saidas[Conta Financeira],X!$E$3)+SUMIFS(Cadastros!$D$6:$D$19,Cadastros!$E$6:$E$19,"<"&G6,Cadastros!$B$6:$B$19,X!$E$3)+SUMIFS(Transferência_Interna[Valor],Transferência_Interna[Conta de Destino],X!$E$3,Transferência_Interna[Data],"<"&G$6)-SUMIFS(Transferência_Interna[Valor],Transferência_Interna[Conta de Origem],X!$E$3,Transferência_Interna[Data],"<"&G$6) -> 7740 | H8: =SUMIFS(Entradas[Valores],Entradas[Data do Recebimento],"<"&H$6,Entradas[Status],X!$E$2,Entradas[Conta Financeira],X!$E$3)-SUMIFS(Saidas[Valores],Saidas[Data do Pagamento],"<"&H$6,Saidas[Status],X!$E$2,Saidas[Conta Financeira],X!$E$3)+SUMIFS(Cadastros!$D$6:$D$19,Cadastros!$E$6:$E$19,"<"&H6,Cadastros!$B$6:$B$19,X!$E$3)+SUMIFS(Transferência_Interna[Valor],Transferência_Interna[Conta de Destino],X!$E$3,Transferência_Interna[Data],"<"&H$6)-SUMIFS(Transferência_Interna[Valor],Transferência_Interna[Conta de Origem],X!$E$3,Transferência_Interna[Data],"<"&H$6) -> 7740 | I8: =SUMIFS(Entradas[Valores],Entradas[Data do Recebimento],"<"&I$6,Entradas[Status],X!$E$2,Entradas[Conta Financeira],X!$E$3)-SUMIFS(Saidas[Valores],Saidas[Data do Pagamento],"<"&I$6,Saidas[Status],X!$E$2,Saidas[Conta Financeira],X!$E$3)+SUMIFS(Cadastros!$D$6:$D$19,Cadastros!$E$6:$E$19,"<"&I6,Cadastros!$B$6:$B$19,X!$E$3)+SUMIFS(Transferência_Interna[Valor],Transferência_Interna[Conta de Destino],X!$E$3,Transferência_Interna[Data],"<"&I$6)-SUMIFS(Transferência_Interna[Valor],Transferência_Interna[Conta de Origem],X!$E$3,Transferência_Interna[Data],"<"&I$6) -> 7740 | J8: =SUMIFS(Entradas[Valores],Entradas[Data do Recebimento],"<"&J$6,Entradas[Status],X!$E$2,Entradas[Conta Financeira],X!$E$3)-SUMIFS(Saidas[Valores],Saidas[Data do Pagamento],"<"&J$6,Saidas[Status],X!$E$2,Saidas[Conta Financeira],X!$E$3)+SUMIFS(Cadastros!$D$6:$D$19,Cadastros!$E$6:$E$19,"<"&J6,Cadastros!$B$6:$B$19,X!$E$3)+SUMIFS(Transferência_Interna[Valor],Transferência_Interna[Conta de Destino],X!$E$3,Transferência_Interna[Data],"<"&J$6)-SUMIFS(Transferência_Interna[Valor],Transferência_Interna[Conta de Origem],X!$E$3,Transferência_Interna[Data],"<"&J$6) -> 7740 | ... N8: =SUMIFS(Entradas[Valores],Entradas[Data do Recebimento],"<"&N$6,Entradas[Status],X!$E$2,Entradas[Conta Financeira],X!$E$3)-SUMIFS(Saidas[Valores],Saidas[Data do Pagamento],"<"&N$6,Saidas[Status],X!$E$2,Saidas[Conta Financeira],X!$E$3)+SUMIFS(Cadastros!$D$6:$D$19,Cadastros!$E$6:$E$19,"<"&N6,Cadastros!$B$6:$B$19,X!$E$3)+SUMIFS(Transferência_Interna[Valor],Transferência_Interna[Conta de Destino],X!$E$3,Transferência_Interna[Data],"<"&N$6)-SUMIFS(Transferência_Interna[Valor],Transferência_Interna[Conta de Origem],X!$E$3,Transferência_Interna[Data],"<"&N$6) -> -34673
B9: Entradas | C9: =SUM(C10:C13) -> 0 | D9: =SUM(D10:D13) -> 0 | E9: =SUM(E10:E13) -> 0 | F9: =SUM(F10:F13) -> 0 | G9: =SUM(G10:G13) -> 0 | H9: =SUM(H10:H13) -> 0 | I9: =SUM(I10:I13) -> 0 | J9: =SUM(J10:J13) -> 0 | ... N9: =SUM(N10:N13) -> 3700 | O9: =SUM(C9:N9) -> 16600
B10: =X!V2 -> Receitas Operacionais | C10: =SUMIFS(Entradas[Valores],Entradas[Data do Recebimento],">="&C$6,Entradas[Data do Recebimento],"<"&EDATE(C$6,1),Entradas[Categoria],$B10,Entradas[Status],X!$E$2,Entradas[Conta Financeira],X!$E$3,Entradas[Centro de Custos],X!$E$4) -> 0 | D10: =SUMIFS(Entradas[Valores],Entradas[Data do Recebimento],">="&D$6,Entradas[Data do Recebimento],"<"&EDATE(D$6,1),Entradas[Categoria],$B10,Entradas[Status],X!$E$2,Entradas[Conta Financeira],X!$E$3,Entradas[Centro de Custos],X!$E$4) -> 0 | E10: =SUMIFS(Entradas[Valores],Entradas[Data do Recebimento],">="&E$6,Entradas[Data do Recebimento],"<"&EDATE(E$6,1),Entradas[Categoria],$B10,Entradas[Status],X!$E$2,Entradas[Conta Financeira],X!$E$3,Entradas[Centro de Custos],X!$E$4) -> 0 | F10: =SUMIFS(Entradas[Valores],Entradas[Data do Recebimento],">="&F$6,Entradas[Data do Recebimento],"<"&EDATE(F$6,1),Entradas[Categoria],$B10,Entradas[Status],X!$E$2,Entradas[Conta Financeira],X!$E$3,Entradas[Centro de Custos],X!$E$4) -> 0 | G10: =SUMIFS(Entradas[Valores],Entradas[Data do Recebimento],">="&G$6,Entradas[Data do Recebimento],"<"&EDATE(G$6,1),Entradas[Categoria],$B10,Entradas[Status],X!$E$2,Entradas[Conta Financeira],X!$E$3,Entradas[Centro de Custos],X!$E$4) -> 0 | H10: =SUMIFS(Entradas[Valores],Entradas[Data do Recebimento],">="&H$6,Entradas[Data do Recebimento],"<"&EDATE(H$6,1),Entradas[Categoria],$B10,Entradas[Status],X!$E$2,Entradas[Conta Financeira],X!$E$3,Entradas[Centro de Custos],X!$E$4) -> 0 | I10: =SUMIFS(Entradas[Valores],Entradas[Data do Recebimento],">="&I$6,Entradas[Data do Recebimento],"<"&EDATE(I$6,1),Entradas[Categoria],$B10,Entradas[Status],X!$E$2,Entradas[Conta Financeira],X!$E$3,Entradas[Centro de Custos],X!$E$4) -> 0 | J10: =SUMIFS(Entradas[Valores],Entradas[Data do Recebimento],">="&J$6,Entradas[Data do Recebimento],"<"&EDATE(J$6,1),Entradas[Categoria],$B10,Entradas[Status],X!$E$2,Entradas[Conta Financeira],X!$E$3,Entradas[Centro de Custos],X!$E$4) -> 0 | ... N10: =SUMIFS(Entradas[Valores],Entradas[Data do Recebimento],">="&N$6,Entradas[Data do Recebimento],"<"&EDATE(N$6,1),Entradas[Categoria],$B10,Entradas[Status],X!$E$2,Entradas[Conta Financeira],X!$E$3,Entradas[Centro de Custos],X!$E$4) -> 3700 | O10: =SUM(C10:N10) -> 6600
B11: =X!V3 -> Outras Receitas Operacionais | C11: =SUMIFS(Entradas[Valores],Entradas[Data do Recebimento],">="&C$6,Entradas[Data do Recebimento],"<"&EDATE(C$6,1),Entradas[Categoria],$B11,Entradas[Status],X!$E$2,Entradas[Conta Financeira],X!$E$3,Entradas[Centro de Custos],X!$E$4) -> 0 | D11: =SUMIFS(Entradas[Valores],Entradas[Data do Recebimento],">="&D$6,Entradas[Data do Recebimento],"<"&EDATE(D$6,1),Entradas[Categoria],$B11,Entradas[Status],X!$E$2,Entradas[Conta Financeira],X!$E$3,Entradas[Centro de Custos],X!$E$4) -> 0 | E11: =SUMIFS(Entradas[Valores],Entradas[Data do Recebimento],">="&E$6,Entradas[Data do Recebimento],"<"&EDATE(E$6,1),Entradas[Categoria],$B11,Entradas[Status],X!$E$2,Entradas[Conta Financeira],X!$E$3,Entradas[Centro de Custos],X!$E$4) -> 0 | F11: =SUMIFS(Entradas[Valores],Entradas[Data do Recebimento],">="&F$6,Entradas[Data do Recebimento],"<"&EDATE(F$6,1),Entradas[Categoria],$B11,Entradas[Status],X!$E$2,Entradas[Conta Financeira],X!$E$3,Entradas[Centro de Custos],X!$E$4) -> 0 | G11: =SUMIFS(Entradas[Valores],Entradas[Data do Recebimento],">="&G$6,Entradas[Data do Recebimento],"<"&EDATE(G$6,1),Entradas[Categoria],$B11,Entradas[Status],X!$E$2,Entradas[Conta Financeira],X!$E$3,Entradas[Centro de Custos],X!$E$4) -> 0 | H11: =SUMIFS(Entradas[Valores],Entradas[Data do Recebimento],">="&H$6,Entradas[Data do Recebimento],"<"&EDATE(H$6,1),Entradas[Categoria],$B11,Entradas[Status],X!$E$2,Entradas[Conta Financeira],X!$E$3,Entradas[Centro de Custos],X!$E$4) -> 0 | I11: =SUMIFS(Entradas[Valores],Entradas[Data do Recebimento],">="&I$6,Entradas[Data do Recebimento],"<"&EDATE(I$6,1),Entradas[Categoria],$B11,Entradas[Status],X!$E$2,Entradas[Conta Financeira],X!$E$3,Entradas[Centro de Custos],X!$E$4) -> 0 | J11: =SUMIFS(Entradas[Valores],Entradas[Data do Recebimento],">="&J$6,Entradas[Data do Recebimento],"<"&EDATE(J$6,1),Entradas[Categoria],$B11,Entradas[Status],X!$E$2,Entradas[Conta Financeira],X!$E$3,Entradas[Centro de Custos],X!$E$4) -> 0 | ... N11: =SUMIFS(Entradas[Valores],Entradas[Data do Recebimento],">="&N$6,Entradas[Data do Recebimento],"<"&EDATE(N$6,1),Entradas[Categoria],$B11,Entradas[Status],X!$E$2,Entradas[Conta Financeira],X!$E$3,Entradas[Centro de Custos],X!$E$4) -> 0 | O11: =SUM(C11:N11) -> 0
B12: =X!V4 -> Receitas Financeiras | C12: =SUMIFS(Entradas[Valores],Entradas[Data do Recebimento],">="&C$6,Entradas[Data do Recebimento],"<"&EDATE(C$6,1),Entradas[Categoria],$B12,Entradas[Status],X!$E$2,Entradas[Conta Financeira],X!$E$3,Entradas[Centro de Custos],X!$E$4) -> 0 | D12: =SUMIFS(Entradas[Valores],Entradas[Data do Recebimento],">="&D$6,Entradas[Data do Recebimento],"<"&EDATE(D$6,1),Entradas[Categoria],$B12,Entradas[Status],X!$E$2,Entradas[Conta Financeira],X!$E$3,Entradas[Centro de Custos],X!$E$4) -> 0 | E12: =SUMIFS(Entradas[Valores],Entradas[Data do Recebimento],">="&E$6,Entradas[Data do Recebimento],"<"&EDATE(E$6,1),Entradas[Categoria],$B12,Entradas[Status],X!$E$2,Entradas[Conta Financeira],X!$E$3,Entradas[Centro de Custos],X!$E$4) -> 0 | F12: =SUMIFS(Entradas[Valores],Entradas[Data do Recebimento],">="&F$6,Entradas[Data do Recebimento],"<"&EDATE(F$6,1),Entradas[Categoria],$B12,Entradas[Status],X!$E$2,Entradas[Conta Financeira],X!$E$3,Entradas[Centro de Custos],X!$E$4) -> 0 | G12: =SUMIFS(Entradas[Valores],Entradas[Data do Recebimento],">="&G$6,Entradas[Data do Recebimento],"<"&EDATE(G$6,1),Entradas[Categoria],$B12,Entradas[Status],X!$E$2,Entradas[Conta Financeira],X!$E$3,Entradas[Centro de Custos],X!$E$4) -> 0 | H12: =SUMIFS(Entradas[Valores],Entradas[Data do Recebimento],">="&H$6,Entradas[Data do Recebimento],"<"&EDATE(H$6,1),Entradas[Categoria],$B12,Entradas[Status],X!$E$2,Entradas[Conta Financeira],X!$E$3,Entradas[Centro de Custos],X!$E$4) -> 0 | I12: =SUMIFS(Entradas[Valores],Entradas[Data do Recebimento],">="&I$6,Entradas[Data do Recebimento],"<"&EDATE(I$6,1),Entradas[Categoria],$B12,Entradas[Status],X!$E$2,Entradas[Conta Financeira],X!$E$3,Entradas[Centro de Custos],X!$E$4) -> 0 | J12: =SUMIFS(Entradas[Valores],Entradas[Data do Recebimento],">="&J$6,Entradas[Data do Recebimento],"<"&EDATE(J$6,1),Entradas[Categoria],$B12,Entradas[Status],X!$E$2,Entradas[Conta Financeira],X!$E$3,Entradas[Centro de Custos],X!$E$4) -> 0 | ... N12: =SUMIFS(Entradas[Valores],Entradas[Data do Recebimento],">="&N$6,Entradas[Data do Recebimento],"<"&EDATE(N$6,1),Entradas[Categoria],$B12,Entradas[Status],X!$E$2,Entradas[Conta Financeira],X!$E$3,Entradas[Centro de Custos],X!$E$4) -> 0 | O12: =SUM(C12:N12) -> 0
B13: =X!V5 -> Receitas não operacionais | C13: =SUMIFS(Entradas[Valores],Entradas[Data do Recebimento],">="&C$6,Entradas[Data do Recebimento],"<"&EDATE(C$6,1),Entradas[Categoria],$B13,Entradas[Status],X!$E$2,Entradas[Conta Financeira],X!$E$3,Entradas[Centro de Custos],X!$E$4) -> 0 | D13: =SUMIFS(Entradas[Valores],Entradas[Data do Recebimento],">="&D$6,Entradas[Data do Recebimento],"<"&EDATE(D$6,1),Entradas[Categoria],$B13,Entradas[Status],X!$E$2,Entradas[Conta Financeira],X!$E$3,Entradas[Centro de Custos],X!$E$4) -> 0 | E13: =SUMIFS(Entradas[Valores],Entradas[Data do Recebimento],">="&E$6,Entradas[Data do Recebimento],"<"&EDATE(E$6,1),Entradas[Categoria],$B13,Entradas[Status],X!$E$2,Entradas[Conta Financeira],X!$E$3,Entradas[Centro de Custos],X!$E$4) -> 0 | F13: =SUMIFS(Entradas[Valores],Entradas[Data do Recebimento],">="&F$6,Entradas[Data do Recebimento],"<"&EDATE(F$6,1),Entradas[Categoria],$B13,Entradas[Status],X!$E$2,Entradas[Conta Financeira],X!$E$3,Entradas[Centro de Custos],X!$E$4) -> 0 | G13: =SUMIFS(Entradas[Valores],Entradas[Data do Recebimento],">="&G$6,Entradas[Data do Recebimento],"<"&EDATE(G$6,1),Entradas[Categoria],$B13,Entradas[Status],X!$E$2,Entradas[Conta Financeira],X!$E$3,Entradas[Centro de Custos],X!$E$4) -> 0 | H13: =SUMIFS(Entradas[Valores],Entradas[Data do Recebimento],">="&H$6,Entradas[Data do Recebimento],"<"&EDATE(H$6,1),Entradas[Categoria],$B13,Entradas[Status],X!$E$2,Entradas[Conta Financeira],X!$E$3,Entradas[Centro de Custos],X!$E$4) -> 0 | I13: =SUMIFS(Entradas[Valores],Entradas[Data do Recebimento],">="&I$6,Entradas[Data do Recebimento],"<"&EDATE(I$6,1),Entradas[Categoria],$B13,Entradas[Status],X!$E$2,Entradas[Conta Financeira],X!$E$3,Entradas[Centro de Custos],X!$E$4) -> 0 | J13: =SUMIFS(Entradas[Valores],Entradas[Data do Recebimento],">="&J$6,Entradas[Data do Recebimento],"<"&EDATE(J$6,1),Entradas[Categoria],$B13,Entradas[Status],X!$E$2,Entradas[Conta Financeira],X!$E$3,Entradas[Centro de Custos],X!$E$4) -> 0 | ... N13: =SUMIFS(Entradas[Valores],Entradas[Data do Recebimento],">="&N$6,Entradas[Data do Recebimento],"<"&EDATE(N$6,1),Entradas[Categoria],$B13,Entradas[Status],X!$E$2,Entradas[Conta Financeira],X!$E$3,Entradas[Centro de Custos],X!$E$4) -> 0 | O13: =SUM(C13:N13) -> 10000
B14: Saídas | C14: =SUM(C15:C24) -> 0 | D14: =SUM(D15:D24) -> 0 | E14: =SUM(E15:E24) -> 0 | F14: =SUM(F15:F24) -> 0 | G14: =SUM(G15:G24) -> 0 | H14: =SUM(H15:H24) -> 0 | I14: =SUM(I15:I24) -> 0 | J14: =SUM(J15:J24) -> 0 | ... N14: =SUM(N15:N24) -> 0 | O14: =SUM(C14:N14) -> 55313
B15: =X!V6 -> Deduções sobre vendas | C15: =SUMIFS(Saidas[Valores],Saidas[Data do Pagamento],">="&C$6,Saidas[Data do Pagamento],"<"&EDATE(C$6,1),Saidas[Categoria],$B15,Saidas[Status],X!$E$2,Saidas[Conta Financeira],X!$E$3,Saidas[Centro de Custos],X!$E$4) -> 0 | D15: =SUMIFS(Saidas[Valores],Saidas[Data do Pagamento],">="&D$6,Saidas[Data do Pagamento],"<"&EDATE(D$6,1),Saidas[Categoria],$B15,Saidas[Status],X!$E$2,Saidas[Conta Financeira],X!$E$3,Saidas[Centro de Custos],X!$E$4) -> 0 | E15: =SUMIFS(Saidas[Valores],Saidas[Data do Pagamento],">="&E$6,Saidas[Data do Pagamento],"<"&EDATE(E$6,1),Saidas[Categoria],$B15,Saidas[Status],X!$E$2,Saidas[Conta Financeira],X!$E$3,Saidas[Centro de Custos],X!$E$4) -> 0 | F15: =SUMIFS(Saidas[Valores],Saidas[Data do Pagamento],">="&F$6,Saidas[Data do Pagamento],"<"&EDATE(F$6,1),Saidas[Categoria],$B15,Saidas[Status],X!$E$2,Saidas[Conta Financeira],X!$E$3,Saidas[Centro de Custos],X!$E$4) -> 0 | G15: =SUMIFS(Saidas[Valores],Saidas[Data do Pagamento],">="&G$6,Saidas[Data do Pagamento],"<"&EDATE(G$6,1),Saidas[Categoria],$B15,Saidas[Status],X!$E$2,Saidas[Conta Financeira],X!$E$3,Saidas[Centro de Custos],X!$E$4) -> 0 | H15: =SUMIFS(Saidas[Valores],Saidas[Data do Pagamento],">="&H$6,Saidas[Data do Pagamento],"<"&EDATE(H$6,1),Saidas[Categoria],$B15,Saidas[Status],X!$E$2,Saidas[Conta Financeira],X!$E$3,Saidas[Centro de Custos],X!$E$4) -> 0 | I15: =SUMIFS(Saidas[Valores],Saidas[Data do Pagamento],">="&I$6,Saidas[Data do Pagamento],"<"&EDATE(I$6,1),Saidas[Categoria],$B15,Saidas[Status],X!$E$2,Saidas[Conta Financeira],X!$E$3,Saidas[Centro de Custos],X!$E$4) -> 0 | J15: =SUMIFS(Saidas[Valores],Saidas[Data do Pagamento],">="&J$6,Saidas[Data do Pagamento],"<"&EDATE(J$6,1),Saidas[Categoria],$B15,Saidas[Status],X!$E$2,Saidas[Conta Financeira],X!$E$3,Saidas[Centro de Custos],X!$E$4) -> 0 | ... N15: =SUMIFS(Saidas[Valores],Saidas[Data do Pagamento],">="&N$6,Saidas[Data do Pagamento],"<"&EDATE(N$6,1),Saidas[Categoria],$B15,Saidas[Status],X!$E$2,Saidas[Conta Financeira],X!$E$3,Saidas[Centro de Custos],X!$E$4) -> 0 | O15: =SUM(C15:N15) -> 0
B16: =X!V7 -> Custo das Vendas | C16: =SUMIFS(Saidas[Valores],Saidas[Data do Pagamento],">="&C$6,Saidas[Data do Pagamento],"<"&EDATE(C$6,1),Saidas[Categoria],$B16,Saidas[Status],X!$E$2,Saidas[Conta Financeira],X!$E$3,Saidas[Centro de Custos],X!$E$4) -> 0 | D16: =SUMIFS(Saidas[Valores],Saidas[Data do Pagamento],">="&D$6,Saidas[Data do Pagamento],"<"&EDATE(D$6,1),Saidas[Categoria],$B16,Saidas[Status],X!$E$2,Saidas[Conta Financeira],X!$E$3,Saidas[Centro de Custos],X!$E$4) -> 0 | E16: =SUMIFS(Saidas[Valores],Saidas[Data do Pagamento],">="&E$6,Saidas[Data do Pagamento],"<"&EDATE(E$6,1),Saidas[Categoria],$B16,Saidas[Status],X!$E$2,Saidas[Conta Financeira],X!$E$3,Saidas[Centro de Custos],X!$E$4) -> 0 | F16: =SUMIFS(Saidas[Valores],Saidas[Data do Pagamento],">="&F$6,Saidas[Data do Pagamento],"<"&EDATE(F$6,1),Saidas[Categoria],$B16,Saidas[Status],X!$E$2,Saidas[Conta Financeira],X!$E$3,Saidas[Centro de Custos],X!$E$4) -> 0 | G16: =SUMIFS(Saidas[Valores],Saidas[Data do Pagamento],">="&G$6,Saidas[Data do Pagamento],"<"&EDATE(G$6,1),Saidas[Categoria],$B16,Saidas[Status],X!$E$2,Saidas[Conta Financeira],X!$E$3,Saidas[Centro de Custos],X!$E$4) -> 0 | H16: =SUMIFS(Saidas[Valores],Saidas[Data do Pagamento],">="&H$6,Saidas[Data do Pagamento],"<"&EDATE(H$6,1),Saidas[Categoria],$B16,Saidas[Status],X!$E$2,Saidas[Conta Financeira],X!$E$3,Saidas[Centro de Custos],X!$E$4) -> 0 | I16: =SUMIFS(Saidas[Valores],Saidas[Data do Pagamento],">="&I$6,Saidas[Data do Pagamento],"<"&EDATE(I$6,1),Saidas[Categoria],$B16,Saidas[Status],X!$E$2,Saidas[Conta Financeira],X!$E$3,Saidas[Centro de Custos],X!$E$4) -> 0 | J16: =SUMIFS(Saidas[Valores],Saidas[Data do Pagamento],">="&J$6,Saidas[Data do Pagamento],"<"&EDATE(J$6,1),Saidas[Categoria],$B16,Saidas[Status],X!$E$2,Saidas[Conta Financeira],X!$E$3,Saidas[Centro de Custos],X!$E$4) -> 0 | ... N16: =SUMIFS(Saidas[Valores],Saidas[Data do Pagamento],">="&N$6,Saidas[Data do Pagamento],"<"&EDATE(N$6,1),Saidas[Categoria],$B16,Saidas[Status],X!$E$2,Saidas[Conta Financeira],X!$E$3,Saidas[Centro de Custos],X!$E$4) -> 0 | O16: =SUM(C16:N16) -> 8123
B17: =X!V8 -> Despesas administrativas | C17: =SUMIFS(Saidas[Valores],Saidas[Data do Pagamento],">="&C$6,Saidas[Data do Pagamento],"<"&EDATE(C$6,1),Saidas[Categoria],$B17,Saidas[Status],X!$E$2,Saidas[Conta Financeira],X!$E$3,Saidas[Centro de Custos],X!$E$4) -> 0 | D17: =SUMIFS(Saidas[Valores],Saidas[Data do Pagamento],">="&D$6,Saidas[Data do Pagamento],"<"&EDATE(D$6,1),Saidas[Categoria],$B17,Saidas[Status],X!$E$2,Saidas[Conta Financeira],X!$E$3,Saidas[Centro de Custos],X!$E$4) -> 0 | E17: =SUMIFS(Saidas[Valores],Saidas[Data do Pagamento],">="&E$6,Saidas[Data do Pagamento],"<"&EDATE(E$6,1),Saidas[Categoria],$B17,Saidas[Status],X!$E$2,Saidas[Conta Financeira],X!$E$3,Saidas[Centro de Custos],X!$E$4) -> 0 | F17: =SUMIFS(Saidas[Valores],Saidas[Data do Pagamento],">="&F$6,Saidas[Data do Pagamento],"<"&EDATE(F$6,1),Saidas[Categoria],$B17,Saidas[Status],X!$E$2,Saidas[Conta Financeira],X!$E$3,Saidas[Centro de Custos],X!$E$4) -> 0 | G17: =SUMIFS(Saidas[Valores],Saidas[Data do Pagamento],">="&G$6,Saidas[Data do Pagamento],"<"&EDATE(G$6,1),Saidas[Categoria],$B17,Saidas[Status],X!$E$2,Saidas[Conta Financeira],X!$E$3,Saidas[Centro de Custos],X!$E$4) -> 0 | H17: =SUMIFS(Saidas[Valores],Saidas[Data do Pagamento],">="&H$6,Saidas[Data do Pagamento],"<"&EDATE(H$6,1),Saidas[Categoria],$B17,Saidas[Status],X!$E$2,Saidas[Conta Financeira],X!$E$3,Saidas[Centro de Custos],X!$E$4) -> 0 | I17: =SUMIFS(Saidas[Valores],Saidas[Data do Pagamento],">="&I$6,Saidas[Data do Pagamento],"<"&EDATE(I$6,1),Saidas[Categoria],$B17,Saidas[Status],X!$E$2,Saidas[Conta Financeira],X!$E$3,Saidas[Centro de Custos],X!$E$4) -> 0 | J17: =SUMIFS(Saidas[Valores],Saidas[Data do Pagamento],">="&J$6,Saidas[Data do Pagamento],"<"&EDATE(J$6,1),Saidas[Categoria],$B17,Saidas[Status],X!$E$2,Saidas[Conta Financeira],X!$E$3,Saidas[Centro de Custos],X!$E$4) -> 0 | ... N17: =SUMIFS(Saidas[Valores],Saidas[Data do Pagamento],">="&N$6,Saidas[Data do Pagamento],"<"&EDATE(N$6,1),Saidas[Categoria],$B17,Saidas[Status],X!$E$2,Saidas[Conta Financeira],X!$E$3,Saidas[Centro de Custos],X!$E$4) -> 0 | O17: =SUM(C17:N17) -> 4270
B18: =X!V9 -> Despesa com Pessoal | C18: =SUMIFS(Saidas[Valores],Saidas[Data do Pagamento],">="&C$6,Saidas[Data do Pagamento],"<"&EDATE(C$6,1),Saidas[Categoria],$B18,Saidas[Status],X!$E$2,Saidas[Conta Financeira],X!$E$3,Saidas[Centro de Custos],X!$E$4) -> 0 | D18: =SUMIFS(Saidas[Valores],Saidas[Data do Pagamento],">="&D$6,Saidas[Data do Pagamento],"<"&EDATE(D$6,1),Saidas[Categoria],$B18,Saidas[Status],X!$E$2,Saidas[Conta Financeira],X!$E$3,Saidas[Centro de Custos],X!$E$4) -> 0 | E18: =SUMIFS(Saidas[Valores],Saidas[Data do Pagamento],">="&E$6,Saidas[Data do Pagamento],"<"&EDATE(E$6,1),Saidas[Categoria],$B18,Saidas[Status],X!$E$2,Saidas[Conta Financeira],X!$E$3,Saidas[Centro de Custos],X!$E$4) -> 0 | F18: =SUMIFS(Saidas[Valores],Saidas[Data do Pagamento],">="&F$6,Saidas[Data do Pagamento],"<"&EDATE(F$6,1),Saidas[Categoria],$B18,Saidas[Status],X!$E$2,Saidas[Conta Financeira],X!$E$3,Saidas[Centro de Custos],X!$E$4) -> 0 | G18: =SUMIFS(Saidas[Valores],Saidas[Data do Pagamento],">="&G$6,Saidas[Data do Pagamento],"<"&EDATE(G$6,1),Saidas[Categoria],$B18,Saidas[Status],X!$E$2,Saidas[Conta Financeira],X!$E$3,Saidas[Centro de Custos],X!$E$4) -> 0 | H18: =SUMIFS(Saidas[Valores],Saidas[Data do Pagamento],">="&H$6,Saidas[Data do Pagamento],"<"&EDATE(H$6,1),Saidas[Categoria],$B18,Saidas[Status],X!$E$2,Saidas[Conta Financeira],X!$E$3,Saidas[Centro de Custos],X!$E$4) -> 0 | I18: =SUMIFS(Saidas[Valores],Saidas[Data do Pagamento],">="&I$6,Saidas[Data do Pagamento],"<"&EDATE(I$6,1),Saidas[Categoria],$B18,Saidas[Status],X!$E$2,Saidas[Conta Financeira],X!$E$3,Saidas[Centro de Custos],X!$E$4) -> 0 | J18: =SUMIFS(Saidas[Valores],Saidas[Data do Pagamento],">="&J$6,Saidas[Data do Pagamento],"<"&EDATE(J$6,1),Saidas[Categoria],$B18,Saidas[Status],X!$E$2,Saidas[Conta Financeira],X!$E$3,Saidas[Centro de Custos],X!$E$4) -> 0 | ... N18: =SUMIFS(Saidas[Valores],Saidas[Data do Pagamento],">="&N$6,Saidas[Data do Pagamento],"<"&EDATE(N$6,1),Saidas[Categoria],$B18,Saidas[Status],X!$E$2,Saidas[Conta Financeira],X!$E$3,Saidas[Centro de Custos],X!$E$4) -> 0 | O18: =SUM(C18:N18) -> 7920
B19: =X!V11 -> Despesa Financeira | C19: =SUMIFS(Saidas[Valores],Saidas[Data do Pagamento],">="&C$6,Saidas[Data do Pagamento],"<"&EDATE(C$6,1),Saidas[Categoria],$B19,Saidas[Status],X!$E$2,Saidas[Conta Financeira],X!$E$3,Saidas[Centro de Custos],X!$E$4) -> 0 | D19: =SUMIFS(Saidas[Valores],Saidas[Data do Pagamento],">="&D$6,Saidas[Data do Pagamento],"<"&EDATE(D$6,1),Saidas[Categoria],$B19,Saidas[Status],X!$E$2,Saidas[Conta Financeira],X!$E$3,Saidas[Centro de Custos],X!$E$4) -> 0 | E19: =SUMIFS(Saidas[Valores],Saidas[Data do Pagamento],">="&E$6,Saidas[Data do Pagamento],"<"&EDATE(E$6,1),Saidas[Categoria],$B19,Saidas[Status],X!$E$2,Saidas[Conta Financeira],X!$E$3,Saidas[Centro de Custos],X!$E$4) -> 0 | F19: =SUMIFS(Saidas[Valores],Saidas[Data do Pagamento],">="&F$6,Saidas[Data do Pagamento],"<"&EDATE(F$6,1),Saidas[Categoria],$B19,Saidas[Status],X!$E$2,Saidas[Conta Financeira],X!$E$3,Saidas[Centro de Custos],X!$E$4) -> 0 | G19: =SUMIFS(Saidas[Valores],Saidas[Data do Pagamento],">="&G$6,Saidas[Data do Pagamento],"<"&EDATE(G$6,1),Saidas[Categoria],$B19,Saidas[Status],X!$E$2,Saidas[Conta Financeira],X!$E$3,Saidas[Centro de Custos],X!$E$4) -> 0 | H19: =SUMIFS(Saidas[Valores],Saidas[Data do Pagamento],">="&H$6,Saidas[Data do Pagamento],"<"&EDATE(H$6,1),Saidas[Categoria],$B19,Saidas[Status],X!$E$2,Saidas[Conta Financeira],X!$E$3,Saidas[Centro de Custos],X!$E$4) -> 0 | I19: =SUMIFS(Saidas[Valores],Saidas[Data do Pagamento],">="&I$6,Saidas[Data do Pagamento],"<"&EDATE(I$6,1),Saidas[Categoria],$B19,Saidas[Status],X!$E$2,Saidas[Conta Financeira],X!$E$3,Saidas[Centro de Custos],X!$E$4) -> 0 | J19: =SUMIFS(Saidas[Valores],Saidas[Data do Pagamento],">="&J$6,Saidas[Data do Pagamento],"<"&EDATE(J$6,1),Saidas[Categoria],$B19,Saidas[Status],X!$E$2,Saidas[Conta Financeira],X!$E$3,Saidas[Centro de Custos],X!$E$4) -> 0 | ... N19: =SUMIFS(Saidas[Valores],Saidas[Data do Pagamento],">="&N$6,Saidas[Data do Pagamento],"<"&EDATE(N$6,1),Saidas[Categoria],$B19,Saidas[Status],X!$E$2,Saidas[Conta Financeira],X!$E$3,Saidas[Centro de Custos],X!$E$4) -> 0 | O19: =SUM(C19:N19) -> 0
B20: =X!V12 -> Despesas não operacionais | C20: =SUMIFS(Saidas[Valores],Saidas[Data do Pagamento],">="&C$6,Saidas[Data do Pagamento],"<"&EDATE(C$6,1),Saidas[Categoria],$B20,Saidas[Status],X!$E$2,Saidas[Conta Financeira],X!$E$3,Saidas[Centro de Custos],X!$E$4) -> 0 | D20: =SUMIFS(Saidas[Valores],Saidas[Data do Pagamento],">="&D$6,Saidas[Data do Pagamento],"<"&EDATE(D$6,1),Saidas[Categoria],$B20,Saidas[Status],X!$E$2,Saidas[Conta Financeira],X!$E$3,Saidas[Centro de Custos],X!$E$4) -> 0 | E20: =SUMIFS(Saidas[Valores],Saidas[Data do Pagamento],">="&E$6,Saidas[Data do Pagamento],"<"&EDATE(E$6,1),Saidas[Categoria],$B20,Saidas[Status],X!$E$2,Saidas[Conta Financeira],X!$E$3,Saidas[Centro de Custos],X!$E$4) -> 0 | F20: =SUMIFS(Saidas[Valores],Saidas[Data do Pagamento],">="&F$6,Saidas[Data do Pagamento],"<"&EDATE(F$6,1),Saidas[Categoria],$B20,Saidas[Status],X!$E$2,Saidas[Conta Financeira],X!$E$3,Saidas[Centro de Custos],X!$E$4) -> 0 | G20: =SUMIFS(Saidas[Valores],Saidas[Data do Pagamento],">="&G$6,Saidas[Data do Pagamento],"<"&EDATE(G$6,1),Saidas[Categoria],$B20,Saidas[Status],X!$E$2,Saidas[Conta Financeira],X!$E$3,Saidas[Centro de Custos],X!$E$4) -> 0 | H20: =SUMIFS(Saidas[Valores],Saidas[Data do Pagamento],">="&H$6,Saidas[Data do Pagamento],"<"&EDATE(H$6,1),Saidas[Categoria],$B20,Saidas[Status],X!$E$2,Saidas[Conta Financeira],X!$E$3,Saidas[Centro de Custos],X!$E$4) -> 0 | I20: =SUMIFS(Saidas[Valores],Saidas[Data do Pagamento],">="&I$6,Saidas[Data do Pagamento],"<"&EDATE(I$6,1),Saidas[Categoria],$B20,Saidas[Status],X!$E$2,Saidas[Conta Financeira],X!$E$3,Saidas[Centro de Custos],X!$E$4) -> 0 | J20: =SUMIFS(Saidas[Valores],Saidas[Data do Pagamento],">="&J$6,Saidas[Data do Pagamento],"<"&EDATE(J$6,1),Saidas[Categoria],$B20,Saidas[Status],X!$E$2,Saidas[Conta Financeira],X!$E$3,Saidas[Centro de Custos],X!$E$4) -> 0 | ... N20: =SUMIFS(Saidas[Valores],Saidas[Data do Pagamento],">="&N$6,Saidas[Data do Pagamento],"<"&EDATE(N$6,1),Saidas[Categoria],$B20,Saidas[Status],X!$E$2,Saidas[Conta Financeira],X!$E$3,Saidas[Centro de Custos],X!$E$4) -> 0 | O20: =SUM(C20:N20) -> 35000
B21: =X!V13 -> Impostos | C21: =SUMIFS(Saidas[Valores],Saidas[Data do Pagamento],">="&C$6,Saidas[Data do Pagamento],"<"&EDATE(C$6,1),Saidas[Categoria],$B21,Saidas[Status],X!$E$2,Saidas[Conta Financeira],X!$E$3,Saidas[Centro de Custos],X!$E$4) -> 0 | D21: =SUMIFS(Saidas[Valores],Saidas[Data do Pagamento],">="&D$6,Saidas[Data do Pagamento],"<"&EDATE(D$6,1),Saidas[Categoria],$B21,Saidas[Status],X!$E$2,Saidas[Conta Financeira],X!$E$3,Saidas[Centro de Custos],X!$E$4) -> 0 | E21: =SUMIFS(Saidas[Valores],Saidas[Data do Pagamento],">="&E$6,Saidas[Data do Pagamento],"<"&EDATE(E$6,1),Saidas[Categoria],$B21,Saidas[Status],X!$E$2,Saidas[Conta Financeira],X!$E$3,Saidas[Centro de Custos],X!$E$4) -> 0 | F21: =SUMIFS(Saidas[Valores],Saidas[Data do Pagamento],">="&F$6,Saidas[Data do Pagamento],"<"&EDATE(F$6,1),Saidas[Categoria],$B21,Saidas[Status],X!$E$2,Saidas[Conta Financeira],X!$E$3,Saidas[Centro de Custos],X!$E$4) -> 0 | G21: =SUMIFS(Saidas[Valores],Saidas[Data do Pagamento],">="&G$6,Saidas[Data do Pagamento],"<"&EDATE(G$6,1),Saidas[Categoria],$B21,Saidas[Status],X!$E$2,Saidas[Conta Financeira],X!$E$3,Saidas[Centro de Custos],X!$E$4) -> 0 | H21: =SUMIFS(Saidas[Valores],Saidas[Data do Pagamento],">="&H$6,Saidas[Data do Pagamento],"<"&EDATE(H$6,1),Saidas[Categoria],$B21,Saidas[Status],X!$E$2,Saidas[Conta Financeira],X!$E$3,Saidas[Centro de Custos],X!$E$4) -> 0 | I21: =SUMIFS(Saidas[Valores],Saidas[Data do Pagamento],">="&I$6,Saidas[Data do Pagamento],"<"&EDATE(I$6,1),Saidas[Categoria],$B21,Saidas[Status],X!$E$2,Saidas[Conta Financeira],X!$E$3,Saidas[Centro de Custos],X!$E$4) -> 0 | J21: =SUMIFS(Saidas[Valores],Saidas[Data do Pagamento],">="&J$6,Saidas[Data do Pagamento],"<"&EDATE(J$6,1),Saidas[Categoria],$B21,Saidas[Status],X!$E$2,Saidas[Conta Financeira],X!$E$3,Saidas[Centro de Custos],X!$E$4) -> 0 | ... N21: =SUMIFS(Saidas[Valores],Saidas[Data do Pagamento],">="&N$6,Saidas[Data do Pagamento],"<"&EDATE(N$6,1),Saidas[Categoria],$B21,Saidas[Status],X!$E$2,Saidas[Conta Financeira],X!$E$3,Saidas[Centro de Custos],X!$E$4) -> 0 | O21: =SUM(C21:N21) -> 0
B22: =X!V14 -> Participação e Dividendos | C22: =SUMIFS(Saidas[Valores],Saidas[Data do Pagamento],">="&C$6,Saidas[Data do Pagamento],"<"&EDATE(C$6,1),Saidas[Categoria],$B22,Saidas[Status],X!$E$2,Saidas[Conta Financeira],X!$E$3,Saidas[Centro de Custos],X!$E$4) -> 0 | D22: =SUMIFS(Saidas[Valores],Saidas[Data do Pagamento],">="&D$6,Saidas[Data do Pagamento],"<"&EDATE(D$6,1),Saidas[Categoria],$B22,Saidas[Status],X!$E$2,Saidas[Conta Financeira],X!$E$3,Saidas[Centro de Custos],X!$E$4) -> 0 | E22: =SUMIFS(Saidas[Valores],Saidas[Data do Pagamento],">="&E$6,Saidas[Data do Pagamento],"<"&EDATE(E$6,1),Saidas[Categoria],$B22,Saidas[Status],X!$E$2,Saidas[Conta Financeira],X!$E$3,Saidas[Centro de Custos],X!$E$4) -> 0 | F22: =SUMIFS(Saidas[Valores],Saidas[Data do Pagamento],">="&F$6,Saidas[Data do Pagamento],"<"&EDATE(F$6,1),Saidas[Categoria],$B22,Saidas[Status],X!$E$2,Saidas[Conta Financeira],X!$E$3,Saidas[Centro de Custos],X!$E$4) -> 0 | G22: =SUMIFS(Saidas[Valores],Saidas[Data do Pagamento],">="&G$6,Saidas[Data do Pagamento],"<"&EDATE(G$6,1),Saidas[Categoria],$B22,Saidas[Status],X!$E$2,Saidas[Conta Financeira],X!$E$3,Saidas[Centro de Custos],X!$E$4) -> 0 | H22: =SUMIFS(Saidas[Valores],Saidas[Data do Pagamento],">="&H$6,Saidas[Data do Pagamento],"<"&EDATE(H$6,1),Saidas[Categoria],$B22,Saidas[Status],X!$E$2,Saidas[Conta Financeira],X!$E$3,Saidas[Centro de Custos],X!$E$4) -> 0 | I22: =SUMIFS(Saidas[Valores],Saidas[Data do Pagamento],">="&I$6,Saidas[Data do Pagamento],"<"&EDATE(I$6,1),Saidas[Categoria],$B22,Saidas[Status],X!$E$2,Saidas[Conta Financeira],X!$E$3,Saidas[Centro de Custos],X!$E$4) -> 0 | J22: =SUMIFS(Saidas[Valores],Saidas[Data do Pagamento],">="&J$6,Saidas[Data do Pagamento],"<"&EDATE(J$6,1),Saidas[Categoria],$B22,Saidas[Status],X!$E$2,Saidas[Conta Financeira],X!$E$3,Saidas[Centro de Custos],X!$E$4) -> 0 | ... N22: =SUMIFS(Saidas[Valores],Saidas[Data do Pagamento],">="&N$6,Saidas[Data do Pagamento],"<"&EDATE(N$6,1),Saidas[Categoria],$B22,Saidas[Status],X!$E$2,Saidas[Conta Financeira],X!$E$3,Saidas[Centro de Custos],X!$E$4) -> 0 | O22: =SUM(C22:N22) -> 0
B23: =X!V15 | C23: =SUMIFS(Saidas[Valores],Saidas[Data do Pagamento],">="&C$6,Saidas[Data do Pagamento],"<"&EDATE(C$6,1),Saidas[Categoria],$B23,Saidas[Status],X!$E$2,Saidas[Conta Financeira],X!$E$3,Saidas[Centro de Custos],X!$E$4) -> 0 | D23: =SUMIFS(Saidas[Valores],Saidas[Data do Pagamento],">="&D$6,Saidas[Data do Pagamento],"<"&EDATE(D$6,1),Saidas[Categoria],$B23,Saidas[Status],X!$E$2,Saidas[Conta Financeira],X!$E$3,Saidas[Centro de Custos],X!$E$4) -> 0 | E23: =SUMIFS(Saidas[Valores],Saidas[Data do Pagamento],">="&E$6,Saidas[Data do Pagamento],"<"&EDATE(E$6,1),Saidas[Categoria],$B23,Saidas[Status],X!$E$2,Saidas[Conta Financeira],X!$E$3,Saidas[Centro de Custos],X!$E$4) -> 0 | F23: =SUMIFS(Saidas[Valores],Saidas[Data do Pagamento],">="&F$6,Saidas[Data do Pagamento],"<"&EDATE(F$6,1),Saidas[Categoria],$B23,Saidas[Status],X!$E$2,Saidas[Conta Financeira],X!$E$3,Saidas[Centro de Custos],X!$E$4) -> 0 | G23: =SUMIFS(Saidas[Valores],Saidas[Data do Pagamento],">="&G$6,Saidas[Data do Pagamento],"<"&EDATE(G$6,1),Saidas[Categoria],$B23,Saidas[Status],X!$E$2,Saidas[Conta Financeira],X!$E$3,Saidas[Centro de Custos],X!$E$4) -> 0 | H23: =SUMIFS(Saidas[Valores],Saidas[Data do Pagamento],">="&H$6,Saidas[Data do Pagamento],"<"&EDATE(H$6,1),Saidas[Categoria],$B23,Saidas[Status],X!$E$2,Saidas[Conta Financeira],X!$E$3,Saidas[Centro de Custos],X!$E$4) -> 0 | I23: =SUMIFS(Saidas[Valores],Saidas[Data do Pagamento],">="&I$6,Saidas[Data do Pagamento],"<"&EDATE(I$6,1),Saidas[Categoria],$B23,Saidas[Status],X!$E$2,Saidas[Conta Financeira],X!$E$3,Saidas[Centro de Custos],X!$E$4) -> 0 | J23: =SUMIFS(Saidas[Valores],Saidas[Data do Pagamento],">="&J$6,Saidas[Data do Pagamento],"<"&EDATE(J$6,1),Saidas[Categoria],$B23,Saidas[Status],X!$E$2,Saidas[Conta Financeira],X!$E$3,Saidas[Centro de Custos],X!$E$4) -> 0 | ... N23: =SUMIFS(Saidas[Valores],Saidas[Data do Pagamento],">="&N$6,Saidas[Data do Pagamento],"<"&EDATE(N$6,1),Saidas[Categoria],$B23,Saidas[Status],X!$E$2,Saidas[Conta Financeira],X!$E$3,Saidas[Centro de Custos],X!$E$4) -> 0 | O23: =SUM(C23:N23) -> 0
B24: =X!V16 | C24: =SUMIFS(Saidas[Valores],Saidas[Data do Pagamento],">="&C$6,Saidas[Data do Pagamento],"<"&EDATE(C$6,1),Saidas[Categoria],$B24,Saidas[Status],X!$E$2,Saidas[Conta Financeira],X!$E$3,Saidas[Centro de Custos],X!$E$4) -> 0 | D24: =SUMIFS(Saidas[Valores],Saidas[Data do Pagamento],">="&D$6,Saidas[Data do Pagamento],"<"&EDATE(D$6,1),Saidas[Categoria],$B24,Saidas[Status],X!$E$2,Saidas[Conta Financeira],X!$E$3,Saidas[Centro de Custos],X!$E$4) -> 0 | E24: =SUMIFS(Saidas[Valores],Saidas[Data do Pagamento],">="&E$6,Saidas[Data do Pagamento],"<"&EDATE(E$6,1),Saidas[Categoria],$B24,Saidas[Status],X!$E$2,Saidas[Conta Financeira],X!$E$3,Saidas[Centro de Custos],X!$E$4) -> 0 | F24: =SUMIFS(Saidas[Valores],Saidas[Data do Pagamento],">="&F$6,Saidas[Data do Pagamento],"<"&EDATE(F$6,1),Saidas[Categoria],$B24,Saidas[Status],X!$E$2,Saidas[Conta Financeira],X!$E$3,Saidas[Centro de Custos],X!$E$4) -> 0 | G24: =SUMIFS(Saidas[Valores],Saidas[Data do Pagamento],">="&G$6,Saidas[Data do Pagamento],"<"&EDATE(G$6,1),Saidas[Categoria],$B24,Saidas[Status],X!$E$2,Saidas[Conta Financeira],X!$E$3,Saidas[Centro de Custos],X!$E$4) -> 0 | H24: =SUMIFS(Saidas[Valores],Saidas[Data do Pagamento],">="&H$6,Saidas[Data do Pagamento],"<"&EDATE(H$6,1),Saidas[Categoria],$B24,Saidas[Status],X!$E$2,Saidas[Conta Financeira],X!$E$3,Saidas[Centro de Custos],X!$E$4) -> 0 | I24: =SUMIFS(Saidas[Valores],Saidas[Data do Pagamento],">="&I$6,Saidas[Data do Pagamento],"<"&EDATE(I$6,1),Saidas[Categoria],$B24,Saidas[Status],X!$E$2,Saidas[Conta Financeira],X!$E$3,Saidas[Centro de Custos],X!$E$4) -> 0 | J24: =SUMIFS(Saidas[Valores],Saidas[Data do Pagamento],">="&J$6,Saidas[Data do Pagamento],"<"&EDATE(J$6,1),Saidas[Categoria],$B24,Saidas[Status],X!$E$2,Saidas[Conta Financeira],X!$E$3,Saidas[Centro de Custos],X!$E$4) -> 0 | ... N24: =SUMIFS(Saidas[Valores],Saidas[Data do Pagamento],">="&N$6,Saidas[Data do Pagamento],"<"&EDATE(N$6,1),Saidas[Categoria],$B24,Saidas[Status],X!$E$2,Saidas[Conta Financeira],X!$E$3,Saidas[Centro de Custos],X!$E$4) -> 0 | O24: =SUM(C24:N24) -> 0
B26: Resultado do Mês | C26: =C9-C14 -> 0 | D26: =D9-D14 -> 0 | E26: =E9-E14 -> 0 | F26: =F9-F14 -> 0 | G26: =G9-G14 -> 0 | H26: =H9-H14 -> 0 | I26: =I9-I14 -> 0 | J26: =J9-J14 -> 0 | ... O26: =O9-O14 -> -38713
B28: Ajuste de Transferência interna | C28: =SUMIFS(Transferência_Interna[Valor],Transferência_Interna[Conta de Destino],X!$E$3,Transferência_Interna[Data],">="&C$6,Transferência_Interna[Data],"<"&EDATE(C$6,1))-SUMIFS(Transferência_Interna[Valor],Transferência_Interna[Conta de Origem],X!$E$3,Transferência_Interna[Data],">="&C$6,Transferência_Interna[Data],"<"&EDATE(C$6,1)) -> 0 | D28: =SUMIFS(Transferência_Interna[Valor],Transferência_Interna[Conta de Destino],X!$E$3,Transferência_Interna[Data],">="&D$6,Transferência_Interna[Data],"<"&EDATE(D$6,1))-SUMIFS(Transferência_Interna[Valor],Transferência_Interna[Conta de Origem],X!$E$3,Transferência_Interna[Data],">="&D$6,Transferência_Interna[Data],"<"&EDATE(D$6,1)) -> 0 | E28: =SUMIFS(Transferência_Interna[Valor],Transferência_Interna[Conta de Destino],X!$E$3,Transferência_Interna[Data],">="&E$6,Transferência_Interna[Data],"<"&EDATE(E$6,1))-SUMIFS(Transferência_Interna[Valor],Transferência_Interna[Conta de Origem],X!$E$3,Transferência_Interna[Data],">="&E$6,Transferência_Interna[Data],"<"&EDATE(E$6,1)) -> 0 | F28: =SUMIFS(Transferência_Interna[Valor],Transferência_Interna[Conta de Destino],X!$E$3,Transferência_Interna[Data],">="&F$6,Transferência_Interna[Data],"<"&EDATE(F$6,1))-SUMIFS(Transferência_Interna[Valor],Transferência_Interna[Conta de Origem],X!$E$3,Transferência_Interna[Data],">="&F$6,Transferência_Interna[Data],"<"&EDATE(F$6,1)) -> 0 | G28: =SUMIFS(Transferência_Interna[Valor],Transferência_Interna[Conta de Destino],X!$E$3,Transferência_Interna[Data],">="&G$6,Transferência_Interna[Data],"<"&EDATE(G$6,1))-SUMIFS(Transferência_Interna[Valor],Transferência_Interna[Conta de Origem],X!$E$3,Transferência_Interna[Data],">="&G$6,Transferência_Interna[Data],"<"&EDATE(G$6,1)) -> 0 | H28: =SUMIFS(Transferência_Interna[Valor],Transferência_Interna[Conta de Destino],X!$E$3,Transferência_Interna[Data],">="&H$6,Transferência_Interna[Data],"<"&EDATE(H$6,1))-SUMIFS(Transferência_Interna[Valor],Transferência_Interna[Conta de Origem],X!$E$3,Transferência_Interna[Data],">="&H$6,Transferência_Interna[Data],"<"&EDATE(H$6,1)) -> 0 | I28: =SUMIFS(Transferência_Interna[Valor],Transferência_Interna[Conta de Destino],X!$E$3,Transferência_Interna[Data],">="&I$6,Transferência_Interna[Data],"<"&EDATE(I$6,1))-SUMIFS(Transferência_Interna[Valor],Transferência_Interna[Conta de Origem],X!$E$3,Transferência_Interna[Data],">="&I$6,Transferência_Interna[Data],"<"&EDATE(I$6,1)) -> 0 | J28: =SUMIFS(Transferência_Interna[Valor],Transferência_Interna[Conta de Destino],X!$E$3,Transferência_Interna[Data],">="&J$6,Transferência_Interna[Data],"<"&EDATE(J$6,1))-SUMIFS(Transferência_Interna[Valor],Transferência_Interna[Conta de Origem],X!$E$3,Transferência_Interna[Data],">="&J$6,Transferência_Interna[Data],"<"&EDATE(J$6,1)) -> 0 | ... N28: =SUMIFS(Transferência_Interna[Valor],Transferência_Interna[Conta de Destino],X!$E$3,Transferência_Interna[Data],">="&N$6,Transferência_Interna[Data],"<"&EDATE(N$6,1))-SUMIFS(Transferência_Interna[Valor],Transferência_Interna[Conta de Origem],X!$E$3,Transferência_Interna[Data],">="&N$6,Transferência_Interna[Data],"<"&EDATE(N$6,1)) -> 0
